INFO:     Will watch for changes in these directories: ['/Users/will/Cursor Project/TradingView/OKX DASHBOARD/backend']
INFO:     Uvicorn running on http://0.0.0.0:8000 (Press CTRL+C to quit)
INFO:     Started reloader process [47012] using StatReload
INFO:     Started server process [47079]
INFO:     Waiting for application startup.
INFO:     Application startup complete.
INFO:     127.0.0.1:53360 - "WebSocket /ws" [accepted]
INFO:     connection closed
ERROR:    Exception in ASGI application
Traceback (most recent call last):
  File "/Library/Frameworks/Python.framework/Versions/3.11/lib/python3.11/site-packages/uvicorn/protocols/websockets/websockets_impl.py", line 332, in asgi_send
    await self.send(data)  # type: ignore[arg-type]
    ^^^^^^^^^^^^^^^^^^^^^
  File "/Library/Frameworks/Python.framework/Versions/3.11/lib/python3.11/site-packages/websockets/legacy/protocol.py", line 620, in send
    await self.ensure_open()
  File "/Library/Frameworks/Python.framework/Versions/3.11/lib/python3.11/site-packages/websockets/legacy/protocol.py", line 921, in ensure_open
    raise self.connection_closed_exc()
websockets.exceptions.ConnectionClosedError: no close frame received or sent

The above exception was the direct cause of the following exception:

Traceback (most recent call last):
  File "/Library/Frameworks/Python.framework/Versions/3.11/lib/python3.11/site-packages/starlette/websockets.py", line 85, in send
    await self._send(message)
  File "/Library/Frameworks/Python.framework/Versions/3.11/lib/python3.11/site-packages/starlette/_exception_handler.py", line 39, in sender
    await send(message)
  File "/Library/Frameworks/Python.framework/Versions/3.11/lib/python3.11/site-packages/uvicorn/protocols/websockets/websockets_impl.py", line 345, in asgi_send
    raise ClientDisconnected from exc
uvicorn.protocols.utils.ClientDisconnected

During handling of the above exception, another exception occurred:

Traceback (most recent call last):
  File "/Library/Frameworks/Python.framework/Versions/3.11/lib/python3.11/site-packages/uvicorn/protocols/websockets/websockets_impl.py", line 244, in run_asgi
    result = await self.app(self.scope, self.asgi_receive, self.asgi_send)  # type: ignore[func-returns-value]
             ^^^^^^^^^^^^^^^^^^^^^^^^^^^^^^^^^^^^^^^^^^^^^^^^^^^^^^^^^^^^^
  File "/Library/Frameworks/Python.framework/Versions/3.11/lib/python3.11/site-packages/uvicorn/middleware/proxy_headers.py", line 60, in __call__
    return await self.app(scope, receive, send)
           ^^^^^^^^^^^^^^^^^^^^^^^^^^^^^^^^^^^^
  File "/Library/Frameworks/Python.framework/Versions/3.11/lib/python3.11/site-packages/fastapi/applications.py", line 1054, in __call__
    await super().__call__(scope, receive, send)
  File "/Library/Frameworks/Python.framework/Versions/3.11/lib/python3.11/site-packages/starlette/applications.py", line 112, in __call__
    await self.middleware_stack(scope, receive, send)
  File "/Library/Frameworks/Python.framework/Versions/3.11/lib/python3.11/site-packages/starlette/middleware/errors.py", line 152, in __call__
    await self.app(scope, receive, send)
  File "/Library/Frameworks/Python.framework/Versions/3.11/lib/python3.11/site-packages/starlette/middleware/cors.py", line 77, in __call__
    await self.app(scope, receive, send)
  File "/Library/Frameworks/Python.framework/Versions/3.11/lib/python3.11/site-packages/starlette/middleware/exceptions.py", line 62, in __call__
    await wrap_app_handling_exceptions(self.app, conn)(scope, receive, send)
  File "/Library/Frameworks/Python.framework/Versions/3.11/lib/python3.11/site-packages/starlette/_exception_handler.py", line 53, in wrapped_app
    raise exc
  File "/Library/Frameworks/Python.framework/Versions/3.11/lib/python3.11/site-packages/starlette/_exception_handler.py", line 42, in wrapped_app
    await app(scope, receive, sender)
  File "/Library/Frameworks/Python.framework/Versions/3.11/lib/python3.11/site-packages/starlette/routing.py", line 714, in __call__
    await self.middleware_stack(scope, receive, send)
  File "/Library/Frameworks/Python.framework/Versions/3.11/lib/python3.11/site-packages/starlette/routing.py", line 734, in app
    await route.handle(scope, receive, send)
  File "/Library/Frameworks/Python.framework/Versions/3.11/lib/python3.11/site-packages/starlette/routing.py", line 362, in handle
    await self.app(scope, receive, send)
  File "/Library/Frameworks/Python.framework/Versions/3.11/lib/python3.11/site-packages/starlette/routing.py", line 95, in app
    await wrap_app_handling_exceptions(app, session)(scope, receive, send)
  File "/Library/Frameworks/Python.framework/Versions/3.11/lib/python3.11/site-packages/starlette/_exception_handler.py", line 53, in wrapped_app
    raise exc
  File "/Library/Frameworks/Python.framework/Versions/3.11/lib/python3.11/site-packages/starlette/_exception_handler.py", line 42, in wrapped_app
    await app(scope, receive, sender)
  File "/Library/Frameworks/Python.framework/Versions/3.11/lib/python3.11/site-packages/starlette/routing.py", line 93, in app
    await func(session)
  File "/Library/Frameworks/Python.framework/Versions/3.11/lib/python3.11/site-packages/fastapi/routing.py", line 383, in app
    await dependant.call(**solved_result.values)
  File "/Users/will/Cursor Project/TradingView/OKX DASHBOARD/backend/main.py", line 165, in websocket_endpoint
    await websocket.send_json({"account": idx, "data": data})
  File "/Library/Frameworks/Python.framework/Versions/3.11/lib/python3.11/site-packages/starlette/websockets.py", line 175, in send_json
    await self.send({"type": "websocket.send", "text": text})
  File "/Library/Frameworks/Python.framework/Versions/3.11/lib/python3.11/site-packages/starlette/websockets.py", line 88, in send
    raise WebSocketDisconnect(code=1006)
starlette.websockets.WebSocketDisconnect
INFO:     127.0.0.1:53364 - "WebSocket /ws" [accepted]
INFO:     connection open
Exception in thread Thread-1 (start_okx_ws):
Traceback (most recent call last):
  File "/Library/Frameworks/Python.framework/Versions/3.11/lib/python3.11/threading.py", line 1045, in _bootstrap_inner
    self.run()
  File "/Library/Frameworks/Python.framework/Versions/3.11/lib/python3.11/threading.py", line 982, in run
    self._target(*self._args, **self._kwargs)
  File "/Users/will/Cursor Project/TradingView/OKX DASHBOARD/backend/main.py", line 153, in start_okx_ws
    loop.run_until_complete(asyncio.gather(*tasks))
  File "/Library/Frameworks/Python.framework/Versions/3.11/lib/python3.11/asyncio/base_events.py", line 653, in run_until_complete
    return future.result()
           ^^^^^^^^^^^^^^^
  File "/Users/will/Cursor Project/TradingView/OKX DASHBOARD/backend/main.py", line 121, in okx_account_ws
    await client.send_json({"account": account_idx, "data": data["data"]})
  File "/Library/Frameworks/Python.framework/Versions/3.11/lib/python3.11/site-packages/starlette/websockets.py", line 175, in send_json
    await self.send({"type": "websocket.send", "text": text})
  File "/Library/Frameworks/Python.framework/Versions/3.11/lib/python3.11/site-packages/starlette/websockets.py", line 97, in send
    raise RuntimeError('Cannot call "send" once a close message has been sent.')
RuntimeError: Cannot call "send" once a close message has been sent.
INFO:     connection closed
INFO:     127.0.0.1:53660 - "WebSocket /ws" [accepted]
INFO:     connection open
ERROR:    Exception in ASGI application
Traceback (most recent call last):
  File "/Library/Frameworks/Python.framework/Versions/3.11/lib/python3.11/site-packages/websockets/legacy/protocol.py", line 945, in transfer_data
    message = await self.read_message()
              ^^^^^^^^^^^^^^^^^^^^^^^^^
  File "/Library/Frameworks/Python.framework/Versions/3.11/lib/python3.11/site-packages/websockets/legacy/protocol.py", line 1015, in read_message
    frame = await self.read_data_frame(max_size=self.max_size)
            ^^^^^^^^^^^^^^^^^^^^^^^^^^^^^^^^^^^^^^^^^^^^^^^^^^
  File "/Library/Frameworks/Python.framework/Versions/3.11/lib/python3.11/site-packages/websockets/legacy/protocol.py", line 1090, in read_data_frame
    frame = await self.read_frame(max_size)
            ^^^^^^^^^^^^^^^^^^^^^^^^^^^^^^^
  File "/Library/Frameworks/Python.framework/Versions/3.11/lib/python3.11/site-packages/websockets/legacy/protocol.py", line 1147, in read_frame
    frame = await Frame.read(
            ^^^^^^^^^^^^^^^^^
  File "/Library/Frameworks/Python.framework/Versions/3.11/lib/python3.11/site-packages/websockets/legacy/framing.py", line 71, in read
    data = await reader(2)
           ^^^^^^^^^^^^^^^
  File "/Library/Frameworks/Python.framework/Versions/3.11/lib/python3.11/asyncio/streams.py", line 730, in readexactly
    raise exceptions.IncompleteReadError(incomplete, n)
asyncio.exceptions.IncompleteReadError: 0 bytes read on a total of 2 expected bytes

The above exception was the direct cause of the following exception:

Traceback (most recent call last):
  File "/Library/Frameworks/Python.framework/Versions/3.11/lib/python3.11/site-packages/uvicorn/protocols/websockets/websockets_impl.py", line 332, in asgi_send
    await self.send(data)  # type: ignore[arg-type]
    ^^^^^^^^^^^^^^^^^^^^^
  File "/Library/Frameworks/Python.framework/Versions/3.11/lib/python3.11/site-packages/websockets/legacy/protocol.py", line 620, in send
    await self.ensure_open()
  File "/Library/Frameworks/Python.framework/Versions/3.11/lib/python3.11/site-packages/websockets/legacy/protocol.py", line 921, in ensure_open
    raise self.connection_closed_exc()
websockets.exceptions.ConnectionClosedError: no close frame received or sent

The above exception was the direct cause of the following exception:

Traceback (most recent call last):
  File "/Library/Frameworks/Python.framework/Versions/3.11/lib/python3.11/site-packages/starlette/websockets.py", line 85, in send
    await self._send(message)
  File "/Library/Frameworks/Python.framework/Versions/3.11/lib/python3.11/site-packages/starlette/_exception_handler.py", line 39, in sender
    await send(message)
  File "/Library/Frameworks/Python.framework/Versions/3.11/lib/python3.11/site-packages/uvicorn/protocols/websockets/websockets_impl.py", line 345, in asgi_send
    raise ClientDisconnected from exc
uvicorn.protocols.utils.ClientDisconnected

During handling of the above exception, another exception occurred:

Traceback (most recent call last):
  File "/Library/Frameworks/Python.framework/Versions/3.11/lib/python3.11/site-packages/uvicorn/protocols/websockets/websockets_impl.py", line 244, in run_asgi
    result = await self.app(self.scope, self.asgi_receive, self.asgi_send)  # type: ignore[func-returns-value]
             ^^^^^^^^^^^^^^^^^^^^^^^^^^^^^^^^^^^^^^^^^^^^^^^^^^^^^^^^^^^^^
  File "/Library/Frameworks/Python.framework/Versions/3.11/lib/python3.11/site-packages/uvicorn/middleware/proxy_headers.py", line 60, in __call__
    return await self.app(scope, receive, send)
           ^^^^^^^^^^^^^^^^^^^^^^^^^^^^^^^^^^^^
  File "/Library/Frameworks/Python.framework/Versions/3.11/lib/python3.11/site-packages/fastapi/applications.py", line 1054, in __call__
    await super().__call__(scope, receive, send)
  File "/Library/Frameworks/Python.framework/Versions/3.11/lib/python3.11/site-packages/starlette/applications.py", line 112, in __call__
    await self.middleware_stack(scope, receive, send)
  File "/Library/Frameworks/Python.framework/Versions/3.11/lib/python3.11/site-packages/starlette/middleware/errors.py", line 152, in __call__
    await self.app(scope, receive, send)
  File "/Library/Frameworks/Python.framework/Versions/3.11/lib/python3.11/site-packages/starlette/middleware/cors.py", line 77, in __call__
    await self.app(scope, receive, send)
  File "/Library/Frameworks/Python.framework/Versions/3.11/lib/python3.11/site-packages/starlette/middleware/exceptions.py", line 62, in __call__
    await wrap_app_handling_exceptions(self.app, conn)(scope, receive, send)
  File "/Library/Frameworks/Python.framework/Versions/3.11/lib/python3.11/site-packages/starlette/_exception_handler.py", line 53, in wrapped_app
    raise exc
  File "/Library/Frameworks/Python.framework/Versions/3.11/lib/python3.11/site-packages/starlette/_exception_handler.py", line 42, in wrapped_app
    await app(scope, receive, sender)
  File "/Library/Frameworks/Python.framework/Versions/3.11/lib/python3.11/site-packages/starlette/routing.py", line 714, in __call__
    await self.middleware_stack(scope, receive, send)
  File "/Library/Frameworks/Python.framework/Versions/3.11/lib/python3.11/site-packages/starlette/routing.py", line 734, in app
    await route.handle(scope, receive, send)
  File "/Library/Frameworks/Python.framework/Versions/3.11/lib/python3.11/site-packages/starlette/routing.py", line 362, in handle
    await self.app(scope, receive, send)
  File "/Library/Frameworks/Python.framework/Versions/3.11/lib/python3.11/site-packages/starlette/routing.py", line 95, in app
    await wrap_app_handling_exceptions(app, session)(scope, receive, send)
  File "/Library/Frameworks/Python.framework/Versions/3.11/lib/python3.11/site-packages/starlette/_exception_handler.py", line 53, in wrapped_app
    raise exc
  File "/Library/Frameworks/Python.framework/Versions/3.11/lib/python3.11/site-packages/starlette/_exception_handler.py", line 42, in wrapped_app
    await app(scope, receive, sender)
  File "/Library/Frameworks/Python.framework/Versions/3.11/lib/python3.11/site-packages/starlette/routing.py", line 93, in app
    await func(session)
  File "/Library/Frameworks/Python.framework/Versions/3.11/lib/python3.11/site-packages/fastapi/routing.py", line 383, in app
    await dependant.call(**solved_result.values)
  File "/Users/will/Cursor Project/TradingView/OKX DASHBOARD/backend/main.py", line 165, in websocket_endpoint
    await websocket.send_json({"account": idx, "data": data})
  File "/Library/Frameworks/Python.framework/Versions/3.11/lib/python3.11/site-packages/starlette/websockets.py", line 175, in send_json
    await self.send({"type": "websocket.send", "text": text})
  File "/Library/Frameworks/Python.framework/Versions/3.11/lib/python3.11/site-packages/starlette/websockets.py", line 88, in send
    raise WebSocketDisconnect(code=1006)
starlette.websockets.WebSocketDisconnect
INFO:     connection closed
INFO:     127.0.0.1:53664 - "WebSocket /ws" [accepted]
INFO:     connection open
INFO:     connection closed
INFO:     127.0.0.1:53687 - "WebSocket /ws" [accepted]
INFO:     connection open
ERROR:    Exception in ASGI application
Traceback (most recent call last):
  File "/Library/Frameworks/Python.framework/Versions/3.11/lib/python3.11/site-packages/uvicorn/protocols/websockets/websockets_impl.py", line 332, in asgi_send
    await self.send(data)  # type: ignore[arg-type]
    ^^^^^^^^^^^^^^^^^^^^^
  File "/Library/Frameworks/Python.framework/Versions/3.11/lib/python3.11/site-packages/websockets/legacy/protocol.py", line 632, in send
    await self.write_frame(True, opcode, data)
  File "/Library/Frameworks/Python.framework/Versions/3.11/lib/python3.11/site-packages/websockets/legacy/protocol.py", line 1191, in write_frame
    await self.drain()
  File "/Library/Frameworks/Python.framework/Versions/3.11/lib/python3.11/site-packages/websockets/legacy/protocol.py", line 1180, in drain
    await self.ensure_open()
  File "/Library/Frameworks/Python.framework/Versions/3.11/lib/python3.11/site-packages/websockets/legacy/protocol.py", line 921, in ensure_open
    raise self.connection_closed_exc()
websockets.exceptions.ConnectionClosedError: no close frame received or sent

The above exception was the direct cause of the following exception:

Traceback (most recent call last):
  File "/Library/Frameworks/Python.framework/Versions/3.11/lib/python3.11/site-packages/starlette/websockets.py", line 85, in send
    await self._send(message)
  File "/Library/Frameworks/Python.framework/Versions/3.11/lib/python3.11/site-packages/starlette/_exception_handler.py", line 39, in sender
    await send(message)
  File "/Library/Frameworks/Python.framework/Versions/3.11/lib/python3.11/site-packages/uvicorn/protocols/websockets/websockets_impl.py", line 345, in asgi_send
    raise ClientDisconnected from exc
uvicorn.protocols.utils.ClientDisconnected

During handling of the above exception, another exception occurred:

Traceback (most recent call last):
  File "/Library/Frameworks/Python.framework/Versions/3.11/lib/python3.11/site-packages/uvicorn/protocols/websockets/websockets_impl.py", line 244, in run_asgi
    result = await self.app(self.scope, self.asgi_receive, self.asgi_send)  # type: ignore[func-returns-value]
             ^^^^^^^^^^^^^^^^^^^^^^^^^^^^^^^^^^^^^^^^^^^^^^^^^^^^^^^^^^^^^
  File "/Library/Frameworks/Python.framework/Versions/3.11/lib/python3.11/site-packages/uvicorn/middleware/proxy_headers.py", line 60, in __call__
    return await self.app(scope, receive, send)
           ^^^^^^^^^^^^^^^^^^^^^^^^^^^^^^^^^^^^
  File "/Library/Frameworks/Python.framework/Versions/3.11/lib/python3.11/site-packages/fastapi/applications.py", line 1054, in __call__
    await super().__call__(scope, receive, send)
  File "/Library/Frameworks/Python.framework/Versions/3.11/lib/python3.11/site-packages/starlette/applications.py", line 112, in __call__
    await self.middleware_stack(scope, receive, send)
  File "/Library/Frameworks/Python.framework/Versions/3.11/lib/python3.11/site-packages/starlette/middleware/errors.py", line 152, in __call__
    await self.app(scope, receive, send)
  File "/Library/Frameworks/Python.framework/Versions/3.11/lib/python3.11/site-packages/starlette/middleware/cors.py", line 77, in __call__
    await self.app(scope, receive, send)
  File "/Library/Frameworks/Python.framework/Versions/3.11/lib/python3.11/site-packages/starlette/middleware/exceptions.py", line 62, in __call__
    await wrap_app_handling_exceptions(self.app, conn)(scope, receive, send)
  File "/Library/Frameworks/Python.framework/Versions/3.11/lib/python3.11/site-packages/starlette/_exception_handler.py", line 53, in wrapped_app
    raise exc
  File "/Library/Frameworks/Python.framework/Versions/3.11/lib/python3.11/site-packages/starlette/_exception_handler.py", line 42, in wrapped_app
    await app(scope, receive, sender)
  File "/Library/Frameworks/Python.framework/Versions/3.11/lib/python3.11/site-packages/starlette/routing.py", line 714, in __call__
    await self.middleware_stack(scope, receive, send)
  File "/Library/Frameworks/Python.framework/Versions/3.11/lib/python3.11/site-packages/starlette/routing.py", line 734, in app
    await route.handle(scope, receive, send)
  File "/Library/Frameworks/Python.framework/Versions/3.11/lib/python3.11/site-packages/starlette/routing.py", line 362, in handle
    await self.app(scope, receive, send)
  File "/Library/Frameworks/Python.framework/Versions/3.11/lib/python3.11/site-packages/starlette/routing.py", line 95, in app
    await wrap_app_handling_exceptions(app, session)(scope, receive, send)
  File "/Library/Frameworks/Python.framework/Versions/3.11/lib/python3.11/site-packages/starlette/_exception_handler.py", line 53, in wrapped_app
    raise exc
  File "/Library/Frameworks/Python.framework/Versions/3.11/lib/python3.11/site-packages/starlette/_exception_handler.py", line 42, in wrapped_app
    await app(scope, receive, sender)
  File "/Library/Frameworks/Python.framework/Versions/3.11/lib/python3.11/site-packages/starlette/routing.py", line 93, in app
    await func(session)
  File "/Library/Frameworks/Python.framework/Versions/3.11/lib/python3.11/site-packages/fastapi/routing.py", line 383, in app
    await dependant.call(**solved_result.values)
  File "/Users/will/Cursor Project/TradingView/OKX DASHBOARD/backend/main.py", line 165, in websocket_endpoint
    await websocket.send_json({"account": idx, "data": data})
  File "/Library/Frameworks/Python.framework/Versions/3.11/lib/python3.11/site-packages/starlette/websockets.py", line 175, in send_json
    await self.send({"type": "websocket.send", "text": text})
  File "/Library/Frameworks/Python.framework/Versions/3.11/lib/python3.11/site-packages/starlette/websockets.py", line 88, in send
    raise WebSocketDisconnect(code=1006)
starlette.websockets.WebSocketDisconnect
INFO:     connection closed
INFO:     127.0.0.1:53691 - "WebSocket /ws" [accepted]
INFO:     connection open
INFO:     connection closed
INFO:     127.0.0.1:53699 - "WebSocket /ws" [accepted]
INFO:     connection open
ERROR:    Exception in ASGI application
Traceback (most recent call last):
  File "/Library/Frameworks/Python.framework/Versions/3.11/lib/python3.11/site-packages/uvicorn/protocols/websockets/websockets_impl.py", line 332, in asgi_send
    await self.send(data)  # type: ignore[arg-type]
    ^^^^^^^^^^^^^^^^^^^^^
  File "/Library/Frameworks/Python.framework/Versions/3.11/lib/python3.11/site-packages/websockets/legacy/protocol.py", line 632, in send
    await self.write_frame(True, opcode, data)
  File "/Library/Frameworks/Python.framework/Versions/3.11/lib/python3.11/site-packages/websockets/legacy/protocol.py", line 1191, in write_frame
    await self.drain()
  File "/Library/Frameworks/Python.framework/Versions/3.11/lib/python3.11/site-packages/websockets/legacy/protocol.py", line 1180, in drain
    await self.ensure_open()
  File "/Library/Frameworks/Python.framework/Versions/3.11/lib/python3.11/site-packages/websockets/legacy/protocol.py", line 921, in ensure_open
    raise self.connection_closed_exc()
websockets.exceptions.ConnectionClosedError: no close frame received or sent

The above exception was the direct cause of the following exception:

Traceback (most recent call last):
  File "/Library/Frameworks/Python.framework/Versions/3.11/lib/python3.11/site-packages/starlette/websockets.py", line 85, in send
    await self._send(message)
  File "/Library/Frameworks/Python.framework/Versions/3.11/lib/python3.11/site-packages/starlette/_exception_handler.py", line 39, in sender
    await send(message)
  File "/Library/Frameworks/Python.framework/Versions/3.11/lib/python3.11/site-packages/uvicorn/protocols/websockets/websockets_impl.py", line 345, in asgi_send
    raise ClientDisconnected from exc
uvicorn.protocols.utils.ClientDisconnected

During handling of the above exception, another exception occurred:

Traceback (most recent call last):
  File "/Library/Frameworks/Python.framework/Versions/3.11/lib/python3.11/site-packages/uvicorn/protocols/websockets/websockets_impl.py", line 244, in run_asgi
    result = await self.app(self.scope, self.asgi_receive, self.asgi_send)  # type: ignore[func-returns-value]
             ^^^^^^^^^^^^^^^^^^^^^^^^^^^^^^^^^^^^^^^^^^^^^^^^^^^^^^^^^^^^^
  File "/Library/Frameworks/Python.framework/Versions/3.11/lib/python3.11/site-packages/uvicorn/middleware/proxy_headers.py", line 60, in __call__
    return await self.app(scope, receive, send)
           ^^^^^^^^^^^^^^^^^^^^^^^^^^^^^^^^^^^^
  File "/Library/Frameworks/Python.framework/Versions/3.11/lib/python3.11/site-packages/fastapi/applications.py", line 1054, in __call__
    await super().__call__(scope, receive, send)
  File "/Library/Frameworks/Python.framework/Versions/3.11/lib/python3.11/site-packages/starlette/applications.py", line 112, in __call__
    await self.middleware_stack(scope, receive, send)
  File "/Library/Frameworks/Python.framework/Versions/3.11/lib/python3.11/site-packages/starlette/middleware/errors.py", line 152, in __call__
    await self.app(scope, receive, send)
  File "/Library/Frameworks/Python.framework/Versions/3.11/lib/python3.11/site-packages/starlette/middleware/cors.py", line 77, in __call__
    await self.app(scope, receive, send)
  File "/Library/Frameworks/Python.framework/Versions/3.11/lib/python3.11/site-packages/starlette/middleware/exceptions.py", line 62, in __call__
    await wrap_app_handling_exceptions(self.app, conn)(scope, receive, send)
  File "/Library/Frameworks/Python.framework/Versions/3.11/lib/python3.11/site-packages/starlette/_exception_handler.py", line 53, in wrapped_app
    raise exc
  File "/Library/Frameworks/Python.framework/Versions/3.11/lib/python3.11/site-packages/starlette/_exception_handler.py", line 42, in wrapped_app
    await app(scope, receive, sender)
  File "/Library/Frameworks/Python.framework/Versions/3.11/lib/python3.11/site-packages/starlette/routing.py", line 714, in __call__
    await self.middleware_stack(scope, receive, send)
  File "/Library/Frameworks/Python.framework/Versions/3.11/lib/python3.11/site-packages/starlette/routing.py", line 734, in app
    await route.handle(scope, receive, send)
  File "/Library/Frameworks/Python.framework/Versions/3.11/lib/python3.11/site-packages/starlette/routing.py", line 362, in handle
    await self.app(scope, receive, send)
  File "/Library/Frameworks/Python.framework/Versions/3.11/lib/python3.11/site-packages/starlette/routing.py", line 95, in app
    await wrap_app_handling_exceptions(app, session)(scope, receive, send)
  File "/Library/Frameworks/Python.framework/Versions/3.11/lib/python3.11/site-packages/starlette/_exception_handler.py", line 53, in wrapped_app
    raise exc
  File "/Library/Frameworks/Python.framework/Versions/3.11/lib/python3.11/site-packages/starlette/_exception_handler.py", line 42, in wrapped_app
    await app(scope, receive, sender)
  File "/Library/Frameworks/Python.framework/Versions/3.11/lib/python3.11/site-packages/starlette/routing.py", line 93, in app
    await func(session)
  File "/Library/Frameworks/Python.framework/Versions/3.11/lib/python3.11/site-packages/fastapi/routing.py", line 383, in app
    await dependant.call(**solved_result.values)
  File "/Users/will/Cursor Project/TradingView/OKX DASHBOARD/backend/main.py", line 165, in websocket_endpoint
    await websocket.send_json({"account": idx, "data": data})
  File "/Library/Frameworks/Python.framework/Versions/3.11/lib/python3.11/site-packages/starlette/websockets.py", line 175, in send_json
    await self.send({"type": "websocket.send", "text": text})
  File "/Library/Frameworks/Python.framework/Versions/3.11/lib/python3.11/site-packages/starlette/websockets.py", line 88, in send
    raise WebSocketDisconnect(code=1006)
starlette.websockets.WebSocketDisconnect
INFO:     connection closed
INFO:     127.0.0.1:53703 - "WebSocket /ws" [accepted]
INFO:     connection open
INFO:     connection closed
INFO:     127.0.0.1:53718 - "WebSocket /ws" [accepted]
INFO:     connection open
ERROR:    Exception in ASGI application
Traceback (most recent call last):
  File "/Library/Frameworks/Python.framework/Versions/3.11/lib/python3.11/site-packages/uvicorn/protocols/websockets/websockets_impl.py", line 332, in asgi_send
    await self.send(data)  # type: ignore[arg-type]
    ^^^^^^^^^^^^^^^^^^^^^
  File "/Library/Frameworks/Python.framework/Versions/3.11/lib/python3.11/site-packages/websockets/legacy/protocol.py", line 632, in send
    await self.write_frame(True, opcode, data)
  File "/Library/Frameworks/Python.framework/Versions/3.11/lib/python3.11/site-packages/websockets/legacy/protocol.py", line 1191, in write_frame
    await self.drain()
  File "/Library/Frameworks/Python.framework/Versions/3.11/lib/python3.11/site-packages/websockets/legacy/protocol.py", line 1180, in drain
    await self.ensure_open()
  File "/Library/Frameworks/Python.framework/Versions/3.11/lib/python3.11/site-packages/websockets/legacy/protocol.py", line 921, in ensure_open
    raise self.connection_closed_exc()
websockets.exceptions.ConnectionClosedError: no close frame received or sent

The above exception was the direct cause of the following exception:

Traceback (most recent call last):
  File "/Library/Frameworks/Python.framework/Versions/3.11/lib/python3.11/site-packages/starlette/websockets.py", line 85, in send
    await self._send(message)
  File "/Library/Frameworks/Python.framework/Versions/3.11/lib/python3.11/site-packages/starlette/_exception_handler.py", line 39, in sender
    await send(message)
  File "/Library/Frameworks/Python.framework/Versions/3.11/lib/python3.11/site-packages/uvicorn/protocols/websockets/websockets_impl.py", line 345, in asgi_send
    raise ClientDisconnected from exc
uvicorn.protocols.utils.ClientDisconnected

During handling of the above exception, another exception occurred:

Traceback (most recent call last):
  File "/Library/Frameworks/Python.framework/Versions/3.11/lib/python3.11/site-packages/uvicorn/protocols/websockets/websockets_impl.py", line 244, in run_asgi
    result = await self.app(self.scope, self.asgi_receive, self.asgi_send)  # type: ignore[func-returns-value]
             ^^^^^^^^^^^^^^^^^^^^^^^^^^^^^^^^^^^^^^^^^^^^^^^^^^^^^^^^^^^^^
  File "/Library/Frameworks/Python.framework/Versions/3.11/lib/python3.11/site-packages/uvicorn/middleware/proxy_headers.py", line 60, in __call__
    return await self.app(scope, receive, send)
           ^^^^^^^^^^^^^^^^^^^^^^^^^^^^^^^^^^^^
  File "/Library/Frameworks/Python.framework/Versions/3.11/lib/python3.11/site-packages/fastapi/applications.py", line 1054, in __call__
    await super().__call__(scope, receive, send)
  File "/Library/Frameworks/Python.framework/Versions/3.11/lib/python3.11/site-packages/starlette/applications.py", line 112, in __call__
    await self.middleware_stack(scope, receive, send)
  File "/Library/Frameworks/Python.framework/Versions/3.11/lib/python3.11/site-packages/starlette/middleware/errors.py", line 152, in __call__
    await self.app(scope, receive, send)
  File "/Library/Frameworks/Python.framework/Versions/3.11/lib/python3.11/site-packages/starlette/middleware/cors.py", line 77, in __call__
    await self.app(scope, receive, send)
  File "/Library/Frameworks/Python.framework/Versions/3.11/lib/python3.11/site-packages/starlette/middleware/exceptions.py", line 62, in __call__
    await wrap_app_handling_exceptions(self.app, conn)(scope, receive, send)
  File "/Library/Frameworks/Python.framework/Versions/3.11/lib/python3.11/site-packages/starlette/_exception_handler.py", line 53, in wrapped_app
    raise exc
  File "/Library/Frameworks/Python.framework/Versions/3.11/lib/python3.11/site-packages/starlette/_exception_handler.py", line 42, in wrapped_app
    await app(scope, receive, sender)
  File "/Library/Frameworks/Python.framework/Versions/3.11/lib/python3.11/site-packages/starlette/routing.py", line 714, in __call__
    await self.middleware_stack(scope, receive, send)
  File "/Library/Frameworks/Python.framework/Versions/3.11/lib/python3.11/site-packages/starlette/routing.py", line 734, in app
    await route.handle(scope, receive, send)
  File "/Library/Frameworks/Python.framework/Versions/3.11/lib/python3.11/site-packages/starlette/routing.py", line 362, in handle
    await self.app(scope, receive, send)
  File "/Library/Frameworks/Python.framework/Versions/3.11/lib/python3.11/site-packages/starlette/routing.py", line 95, in app
    await wrap_app_handling_exceptions(app, session)(scope, receive, send)
  File "/Library/Frameworks/Python.framework/Versions/3.11/lib/python3.11/site-packages/starlette/_exception_handler.py", line 53, in wrapped_app
    raise exc
  File "/Library/Frameworks/Python.framework/Versions/3.11/lib/python3.11/site-packages/starlette/_exception_handler.py", line 42, in wrapped_app
    await app(scope, receive, sender)
  File "/Library/Frameworks/Python.framework/Versions/3.11/lib/python3.11/site-packages/starlette/routing.py", line 93, in app
    await func(session)
  File "/Library/Frameworks/Python.framework/Versions/3.11/lib/python3.11/site-packages/fastapi/routing.py", line 383, in app
    await dependant.call(**solved_result.values)
  File "/Users/will/Cursor Project/TradingView/OKX DASHBOARD/backend/main.py", line 165, in websocket_endpoint
    await websocket.send_json({"account": idx, "data": data})
  File "/Library/Frameworks/Python.framework/Versions/3.11/lib/python3.11/site-packages/starlette/websockets.py", line 175, in send_json
    await self.send({"type": "websocket.send", "text": text})
  File "/Library/Frameworks/Python.framework/Versions/3.11/lib/python3.11/site-packages/starlette/websockets.py", line 88, in send
    raise WebSocketDisconnect(code=1006)
starlette.websockets.WebSocketDisconnect
INFO:     connection closed
INFO:     127.0.0.1:53722 - "WebSocket /ws" [accepted]
INFO:     connection open
INFO:     connection closed
INFO:     127.0.0.1:53797 - "WebSocket /ws" [accepted]
INFO:     connection open
ERROR:    Exception in ASGI application
Traceback (most recent call last):
  File "/Library/Frameworks/Python.framework/Versions/3.11/lib/python3.11/site-packages/uvicorn/protocols/websockets/websockets_impl.py", line 332, in asgi_send
    await self.send(data)  # type: ignore[arg-type]
    ^^^^^^^^^^^^^^^^^^^^^
  File "/Library/Frameworks/Python.framework/Versions/3.11/lib/python3.11/site-packages/websockets/legacy/protocol.py", line 632, in send
    await self.write_frame(True, opcode, data)
  File "/Library/Frameworks/Python.framework/Versions/3.11/lib/python3.11/site-packages/websockets/legacy/protocol.py", line 1191, in write_frame
    await self.drain()
  File "/Library/Frameworks/Python.framework/Versions/3.11/lib/python3.11/site-packages/websockets/legacy/protocol.py", line 1180, in drain
    await self.ensure_open()
  File "/Library/Frameworks/Python.framework/Versions/3.11/lib/python3.11/site-packages/websockets/legacy/protocol.py", line 921, in ensure_open
    raise self.connection_closed_exc()
websockets.exceptions.ConnectionClosedError: no close frame received or sent

The above exception was the direct cause of the following exception:

Traceback (most recent call last):
  File "/Library/Frameworks/Python.framework/Versions/3.11/lib/python3.11/site-packages/starlette/websockets.py", line 85, in send
    await self._send(message)
  File "/Library/Frameworks/Python.framework/Versions/3.11/lib/python3.11/site-packages/starlette/_exception_handler.py", line 39, in sender
    await send(message)
  File "/Library/Frameworks/Python.framework/Versions/3.11/lib/python3.11/site-packages/uvicorn/protocols/websockets/websockets_impl.py", line 345, in asgi_send
    raise ClientDisconnected from exc
uvicorn.protocols.utils.ClientDisconnected

During handling of the above exception, another exception occurred:

Traceback (most recent call last):
  File "/Library/Frameworks/Python.framework/Versions/3.11/lib/python3.11/site-packages/uvicorn/protocols/websockets/websockets_impl.py", line 244, in run_asgi
    result = await self.app(self.scope, self.asgi_receive, self.asgi_send)  # type: ignore[func-returns-value]
             ^^^^^^^^^^^^^^^^^^^^^^^^^^^^^^^^^^^^^^^^^^^^^^^^^^^^^^^^^^^^^
  File "/Library/Frameworks/Python.framework/Versions/3.11/lib/python3.11/site-packages/uvicorn/middleware/proxy_headers.py", line 60, in __call__
    return await self.app(scope, receive, send)
           ^^^^^^^^^^^^^^^^^^^^^^^^^^^^^^^^^^^^
  File "/Library/Frameworks/Python.framework/Versions/3.11/lib/python3.11/site-packages/fastapi/applications.py", line 1054, in __call__
    await super().__call__(scope, receive, send)
  File "/Library/Frameworks/Python.framework/Versions/3.11/lib/python3.11/site-packages/starlette/applications.py", line 112, in __call__
    await self.middleware_stack(scope, receive, send)
  File "/Library/Frameworks/Python.framework/Versions/3.11/lib/python3.11/site-packages/starlette/middleware/errors.py", line 152, in __call__
    await self.app(scope, receive, send)
  File "/Library/Frameworks/Python.framework/Versions/3.11/lib/python3.11/site-packages/starlette/middleware/cors.py", line 77, in __call__
    await self.app(scope, receive, send)
  File "/Library/Frameworks/Python.framework/Versions/3.11/lib/python3.11/site-packages/starlette/middleware/exceptions.py", line 62, in __call__
    await wrap_app_handling_exceptions(self.app, conn)(scope, receive, send)
  File "/Library/Frameworks/Python.framework/Versions/3.11/lib/python3.11/site-packages/starlette/_exception_handler.py", line 53, in wrapped_app
    raise exc
  File "/Library/Frameworks/Python.framework/Versions/3.11/lib/python3.11/site-packages/starlette/_exception_handler.py", line 42, in wrapped_app
    await app(scope, receive, sender)
  File "/Library/Frameworks/Python.framework/Versions/3.11/lib/python3.11/site-packages/starlette/routing.py", line 714, in __call__
    await self.middleware_stack(scope, receive, send)
  File "/Library/Frameworks/Python.framework/Versions/3.11/lib/python3.11/site-packages/starlette/routing.py", line 734, in app
    await route.handle(scope, receive, send)
  File "/Library/Frameworks/Python.framework/Versions/3.11/lib/python3.11/site-packages/starlette/routing.py", line 362, in handle
    await self.app(scope, receive, send)
  File "/Library/Frameworks/Python.framework/Versions/3.11/lib/python3.11/site-packages/starlette/routing.py", line 95, in app
    await wrap_app_handling_exceptions(app, session)(scope, receive, send)
  File "/Library/Frameworks/Python.framework/Versions/3.11/lib/python3.11/site-packages/starlette/_exception_handler.py", line 53, in wrapped_app
    raise exc
  File "/Library/Frameworks/Python.framework/Versions/3.11/lib/python3.11/site-packages/starlette/_exception_handler.py", line 42, in wrapped_app
    await app(scope, receive, sender)
  File "/Library/Frameworks/Python.framework/Versions/3.11/lib/python3.11/site-packages/starlette/routing.py", line 93, in app
    await func(session)
  File "/Library/Frameworks/Python.framework/Versions/3.11/lib/python3.11/site-packages/fastapi/routing.py", line 383, in app
    await dependant.call(**solved_result.values)
  File "/Users/will/Cursor Project/TradingView/OKX DASHBOARD/backend/main.py", line 165, in websocket_endpoint
    await websocket.send_json({"account": idx, "data": data})
  File "/Library/Frameworks/Python.framework/Versions/3.11/lib/python3.11/site-packages/starlette/websockets.py", line 175, in send_json
    await self.send({"type": "websocket.send", "text": text})
  File "/Library/Frameworks/Python.framework/Versions/3.11/lib/python3.11/site-packages/starlette/websockets.py", line 88, in send
    raise WebSocketDisconnect(code=1006)
starlette.websockets.WebSocketDisconnect
INFO:     connection closed
INFO:     127.0.0.1:53801 - "WebSocket /ws" [accepted]
INFO:     connection open
INFO:     connection closed
INFO:     127.0.0.1:53814 - "WebSocket /ws" [accepted]
INFO:     connection open
ERROR:    Exception in ASGI application
Traceback (most recent call last):
  File "/Library/Frameworks/Python.framework/Versions/3.11/lib/python3.11/site-packages/uvicorn/protocols/websockets/websockets_impl.py", line 332, in asgi_send
    await self.send(data)  # type: ignore[arg-type]
    ^^^^^^^^^^^^^^^^^^^^^
  File "/Library/Frameworks/Python.framework/Versions/3.11/lib/python3.11/site-packages/websockets/legacy/protocol.py", line 632, in send
    await self.write_frame(True, opcode, data)
  File "/Library/Frameworks/Python.framework/Versions/3.11/lib/python3.11/site-packages/websockets/legacy/protocol.py", line 1191, in write_frame
    await self.drain()
  File "/Library/Frameworks/Python.framework/Versions/3.11/lib/python3.11/site-packages/websockets/legacy/protocol.py", line 1180, in drain
    await self.ensure_open()
  File "/Library/Frameworks/Python.framework/Versions/3.11/lib/python3.11/site-packages/websockets/legacy/protocol.py", line 921, in ensure_open
    raise self.connection_closed_exc()
websockets.exceptions.ConnectionClosedError: no close frame received or sent

The above exception was the direct cause of the following exception:

Traceback (most recent call last):
  File "/Library/Frameworks/Python.framework/Versions/3.11/lib/python3.11/site-packages/starlette/websockets.py", line 85, in send
    await self._send(message)
  File "/Library/Frameworks/Python.framework/Versions/3.11/lib/python3.11/site-packages/starlette/_exception_handler.py", line 39, in sender
    await send(message)
  File "/Library/Frameworks/Python.framework/Versions/3.11/lib/python3.11/site-packages/uvicorn/protocols/websockets/websockets_impl.py", line 345, in asgi_send
    raise ClientDisconnected from exc
uvicorn.protocols.utils.ClientDisconnected

During handling of the above exception, another exception occurred:

Traceback (most recent call last):
  File "/Library/Frameworks/Python.framework/Versions/3.11/lib/python3.11/site-packages/uvicorn/protocols/websockets/websockets_impl.py", line 244, in run_asgi
    result = await self.app(self.scope, self.asgi_receive, self.asgi_send)  # type: ignore[func-returns-value]
             ^^^^^^^^^^^^^^^^^^^^^^^^^^^^^^^^^^^^^^^^^^^^^^^^^^^^^^^^^^^^^
  File "/Library/Frameworks/Python.framework/Versions/3.11/lib/python3.11/site-packages/uvicorn/middleware/proxy_headers.py", line 60, in __call__
    return await self.app(scope, receive, send)
           ^^^^^^^^^^^^^^^^^^^^^^^^^^^^^^^^^^^^
  File "/Library/Frameworks/Python.framework/Versions/3.11/lib/python3.11/site-packages/fastapi/applications.py", line 1054, in __call__
    await super().__call__(scope, receive, send)
  File "/Library/Frameworks/Python.framework/Versions/3.11/lib/python3.11/site-packages/starlette/applications.py", line 112, in __call__
    await self.middleware_stack(scope, receive, send)
  File "/Library/Frameworks/Python.framework/Versions/3.11/lib/python3.11/site-packages/starlette/middleware/errors.py", line 152, in __call__
    await self.app(scope, receive, send)
  File "/Library/Frameworks/Python.framework/Versions/3.11/lib/python3.11/site-packages/starlette/middleware/cors.py", line 77, in __call__
    await self.app(scope, receive, send)
  File "/Library/Frameworks/Python.framework/Versions/3.11/lib/python3.11/site-packages/starlette/middleware/exceptions.py", line 62, in __call__
    await wrap_app_handling_exceptions(self.app, conn)(scope, receive, send)
  File "/Library/Frameworks/Python.framework/Versions/3.11/lib/python3.11/site-packages/starlette/_exception_handler.py", line 53, in wrapped_app
    raise exc
  File "/Library/Frameworks/Python.framework/Versions/3.11/lib/python3.11/site-packages/starlette/_exception_handler.py", line 42, in wrapped_app
    await app(scope, receive, sender)
  File "/Library/Frameworks/Python.framework/Versions/3.11/lib/python3.11/site-packages/starlette/routing.py", line 714, in __call__
    await self.middleware_stack(scope, receive, send)
  File "/Library/Frameworks/Python.framework/Versions/3.11/lib/python3.11/site-packages/starlette/routing.py", line 734, in app
    await route.handle(scope, receive, send)
  File "/Library/Frameworks/Python.framework/Versions/3.11/lib/python3.11/site-packages/starlette/routing.py", line 362, in handle
    await self.app(scope, receive, send)
  File "/Library/Frameworks/Python.framework/Versions/3.11/lib/python3.11/site-packages/starlette/routing.py", line 95, in app
    await wrap_app_handling_exceptions(app, session)(scope, receive, send)
  File "/Library/Frameworks/Python.framework/Versions/3.11/lib/python3.11/site-packages/starlette/_exception_handler.py", line 53, in wrapped_app
    raise exc
  File "/Library/Frameworks/Python.framework/Versions/3.11/lib/python3.11/site-packages/starlette/_exception_handler.py", line 42, in wrapped_app
    await app(scope, receive, sender)
  File "/Library/Frameworks/Python.framework/Versions/3.11/lib/python3.11/site-packages/starlette/routing.py", line 93, in app
    await func(session)
  File "/Library/Frameworks/Python.framework/Versions/3.11/lib/python3.11/site-packages/fastapi/routing.py", line 383, in app
    await dependant.call(**solved_result.values)
  File "/Users/will/Cursor Project/TradingView/OKX DASHBOARD/backend/main.py", line 165, in websocket_endpoint
    await websocket.send_json({"account": idx, "data": data})
  File "/Library/Frameworks/Python.framework/Versions/3.11/lib/python3.11/site-packages/starlette/websockets.py", line 175, in send_json
    await self.send({"type": "websocket.send", "text": text})
  File "/Library/Frameworks/Python.framework/Versions/3.11/lib/python3.11/site-packages/starlette/websockets.py", line 88, in send
    raise WebSocketDisconnect(code=1006)
starlette.websockets.WebSocketDisconnect
INFO:     connection closed
INFO:     127.0.0.1:53818 - "WebSocket /ws" [accepted]
INFO:     connection open
INFO:     connection closed
INFO:     127.0.0.1:53891 - "WebSocket /ws" [accepted]
INFO:     connection open
ERROR:    Exception in ASGI application
Traceback (most recent call last):
  File "/Library/Frameworks/Python.framework/Versions/3.11/lib/python3.11/site-packages/websockets/legacy/protocol.py", line 945, in transfer_data
    message = await self.read_message()
              ^^^^^^^^^^^^^^^^^^^^^^^^^
  File "/Library/Frameworks/Python.framework/Versions/3.11/lib/python3.11/site-packages/websockets/legacy/protocol.py", line 1015, in read_message
    frame = await self.read_data_frame(max_size=self.max_size)
            ^^^^^^^^^^^^^^^^^^^^^^^^^^^^^^^^^^^^^^^^^^^^^^^^^^
  File "/Library/Frameworks/Python.framework/Versions/3.11/lib/python3.11/site-packages/websockets/legacy/protocol.py", line 1090, in read_data_frame
    frame = await self.read_frame(max_size)
            ^^^^^^^^^^^^^^^^^^^^^^^^^^^^^^^
  File "/Library/Frameworks/Python.framework/Versions/3.11/lib/python3.11/site-packages/websockets/legacy/protocol.py", line 1147, in read_frame
    frame = await Frame.read(
            ^^^^^^^^^^^^^^^^^
  File "/Library/Frameworks/Python.framework/Versions/3.11/lib/python3.11/site-packages/websockets/legacy/framing.py", line 71, in read
    data = await reader(2)
           ^^^^^^^^^^^^^^^
  File "/Library/Frameworks/Python.framework/Versions/3.11/lib/python3.11/asyncio/streams.py", line 730, in readexactly
    raise exceptions.IncompleteReadError(incomplete, n)
asyncio.exceptions.IncompleteReadError: 0 bytes read on a total of 2 expected bytes

The above exception was the direct cause of the following exception:

Traceback (most recent call last):
  File "/Library/Frameworks/Python.framework/Versions/3.11/lib/python3.11/site-packages/uvicorn/protocols/websockets/websockets_impl.py", line 332, in asgi_send
    await self.send(data)  # type: ignore[arg-type]
    ^^^^^^^^^^^^^^^^^^^^^
  File "/Library/Frameworks/Python.framework/Versions/3.11/lib/python3.11/site-packages/websockets/legacy/protocol.py", line 620, in send
    await self.ensure_open()
  File "/Library/Frameworks/Python.framework/Versions/3.11/lib/python3.11/site-packages/websockets/legacy/protocol.py", line 921, in ensure_open
    raise self.connection_closed_exc()
websockets.exceptions.ConnectionClosedError: no close frame received or sent

The above exception was the direct cause of the following exception:

Traceback (most recent call last):
  File "/Library/Frameworks/Python.framework/Versions/3.11/lib/python3.11/site-packages/starlette/websockets.py", line 85, in send
    await self._send(message)
  File "/Library/Frameworks/Python.framework/Versions/3.11/lib/python3.11/site-packages/starlette/_exception_handler.py", line 39, in sender
    await send(message)
  File "/Library/Frameworks/Python.framework/Versions/3.11/lib/python3.11/site-packages/uvicorn/protocols/websockets/websockets_impl.py", line 345, in asgi_send
    raise ClientDisconnected from exc
uvicorn.protocols.utils.ClientDisconnected

During handling of the above exception, another exception occurred:

Traceback (most recent call last):
  File "/Library/Frameworks/Python.framework/Versions/3.11/lib/python3.11/site-packages/uvicorn/protocols/websockets/websockets_impl.py", line 244, in run_asgi
    result = await self.app(self.scope, self.asgi_receive, self.asgi_send)  # type: ignore[func-returns-value]
             ^^^^^^^^^^^^^^^^^^^^^^^^^^^^^^^^^^^^^^^^^^^^^^^^^^^^^^^^^^^^^
  File "/Library/Frameworks/Python.framework/Versions/3.11/lib/python3.11/site-packages/uvicorn/middleware/proxy_headers.py", line 60, in __call__
    return await self.app(scope, receive, send)
           ^^^^^^^^^^^^^^^^^^^^^^^^^^^^^^^^^^^^
  File "/Library/Frameworks/Python.framework/Versions/3.11/lib/python3.11/site-packages/fastapi/applications.py", line 1054, in __call__
    await super().__call__(scope, receive, send)
  File "/Library/Frameworks/Python.framework/Versions/3.11/lib/python3.11/site-packages/starlette/applications.py", line 112, in __call__
    await self.middleware_stack(scope, receive, send)
  File "/Library/Frameworks/Python.framework/Versions/3.11/lib/python3.11/site-packages/starlette/middleware/errors.py", line 152, in __call__
    await self.app(scope, receive, send)
  File "/Library/Frameworks/Python.framework/Versions/3.11/lib/python3.11/site-packages/starlette/middleware/cors.py", line 77, in __call__
    await self.app(scope, receive, send)
  File "/Library/Frameworks/Python.framework/Versions/3.11/lib/python3.11/site-packages/starlette/middleware/exceptions.py", line 62, in __call__
    await wrap_app_handling_exceptions(self.app, conn)(scope, receive, send)
  File "/Library/Frameworks/Python.framework/Versions/3.11/lib/python3.11/site-packages/starlette/_exception_handler.py", line 53, in wrapped_app
    raise exc
  File "/Library/Frameworks/Python.framework/Versions/3.11/lib/python3.11/site-packages/starlette/_exception_handler.py", line 42, in wrapped_app
    await app(scope, receive, sender)
  File "/Library/Frameworks/Python.framework/Versions/3.11/lib/python3.11/site-packages/starlette/routing.py", line 714, in __call__
    await self.middleware_stack(scope, receive, send)
  File "/Library/Frameworks/Python.framework/Versions/3.11/lib/python3.11/site-packages/starlette/routing.py", line 734, in app
    await route.handle(scope, receive, send)
  File "/Library/Frameworks/Python.framework/Versions/3.11/lib/python3.11/site-packages/starlette/routing.py", line 362, in handle
    await self.app(scope, receive, send)
  File "/Library/Frameworks/Python.framework/Versions/3.11/lib/python3.11/site-packages/starlette/routing.py", line 95, in app
    await wrap_app_handling_exceptions(app, session)(scope, receive, send)
  File "/Library/Frameworks/Python.framework/Versions/3.11/lib/python3.11/site-packages/starlette/_exception_handler.py", line 53, in wrapped_app
    raise exc
  File "/Library/Frameworks/Python.framework/Versions/3.11/lib/python3.11/site-packages/starlette/_exception_handler.py", line 42, in wrapped_app
    await app(scope, receive, sender)
  File "/Library/Frameworks/Python.framework/Versions/3.11/lib/python3.11/site-packages/starlette/routing.py", line 93, in app
    await func(session)
  File "/Library/Frameworks/Python.framework/Versions/3.11/lib/python3.11/site-packages/fastapi/routing.py", line 383, in app
    await dependant.call(**solved_result.values)
  File "/Users/will/Cursor Project/TradingView/OKX DASHBOARD/backend/main.py", line 165, in websocket_endpoint
    await websocket.send_json({"account": idx, "data": data})
  File "/Library/Frameworks/Python.framework/Versions/3.11/lib/python3.11/site-packages/starlette/websockets.py", line 175, in send_json
    await self.send({"type": "websocket.send", "text": text})
  File "/Library/Frameworks/Python.framework/Versions/3.11/lib/python3.11/site-packages/starlette/websockets.py", line 88, in send
    raise WebSocketDisconnect(code=1006)
starlette.websockets.WebSocketDisconnect
INFO:     connection closed
INFO:     127.0.0.1:53895 - "WebSocket /ws" [accepted]
INFO:     connection open
INFO:     connection closed
INFO:     127.0.0.1:53991 - "WebSocket /ws" [accepted]
INFO:     connection open
ERROR:    Exception in ASGI application
Traceback (most recent call last):
  File "/Library/Frameworks/Python.framework/Versions/3.11/lib/python3.11/site-packages/uvicorn/protocols/websockets/websockets_impl.py", line 332, in asgi_send
    await self.send(data)  # type: ignore[arg-type]
    ^^^^^^^^^^^^^^^^^^^^^
  File "/Library/Frameworks/Python.framework/Versions/3.11/lib/python3.11/site-packages/websockets/legacy/protocol.py", line 632, in send
    await self.write_frame(True, opcode, data)
  File "/Library/Frameworks/Python.framework/Versions/3.11/lib/python3.11/site-packages/websockets/legacy/protocol.py", line 1191, in write_frame
    await self.drain()
  File "/Library/Frameworks/Python.framework/Versions/3.11/lib/python3.11/site-packages/websockets/legacy/protocol.py", line 1180, in drain
    await self.ensure_open()
  File "/Library/Frameworks/Python.framework/Versions/3.11/lib/python3.11/site-packages/websockets/legacy/protocol.py", line 921, in ensure_open
    raise self.connection_closed_exc()
websockets.exceptions.ConnectionClosedError: no close frame received or sent

The above exception was the direct cause of the following exception:

Traceback (most recent call last):
  File "/Library/Frameworks/Python.framework/Versions/3.11/lib/python3.11/site-packages/starlette/websockets.py", line 85, in send
    await self._send(message)
  File "/Library/Frameworks/Python.framework/Versions/3.11/lib/python3.11/site-packages/starlette/_exception_handler.py", line 39, in sender
    await send(message)
  File "/Library/Frameworks/Python.framework/Versions/3.11/lib/python3.11/site-packages/uvicorn/protocols/websockets/websockets_impl.py", line 345, in asgi_send
    raise ClientDisconnected from exc
uvicorn.protocols.utils.ClientDisconnected

During handling of the above exception, another exception occurred:

Traceback (most recent call last):
  File "/Library/Frameworks/Python.framework/Versions/3.11/lib/python3.11/site-packages/uvicorn/protocols/websockets/websockets_impl.py", line 244, in run_asgi
    result = await self.app(self.scope, self.asgi_receive, self.asgi_send)  # type: ignore[func-returns-value]
             ^^^^^^^^^^^^^^^^^^^^^^^^^^^^^^^^^^^^^^^^^^^^^^^^^^^^^^^^^^^^^
  File "/Library/Frameworks/Python.framework/Versions/3.11/lib/python3.11/site-packages/uvicorn/middleware/proxy_headers.py", line 60, in __call__
    return await self.app(scope, receive, send)
           ^^^^^^^^^^^^^^^^^^^^^^^^^^^^^^^^^^^^
  File "/Library/Frameworks/Python.framework/Versions/3.11/lib/python3.11/site-packages/fastapi/applications.py", line 1054, in __call__
    await super().__call__(scope, receive, send)
  File "/Library/Frameworks/Python.framework/Versions/3.11/lib/python3.11/site-packages/starlette/applications.py", line 112, in __call__
    await self.middleware_stack(scope, receive, send)
  File "/Library/Frameworks/Python.framework/Versions/3.11/lib/python3.11/site-packages/starlette/middleware/errors.py", line 152, in __call__
    await self.app(scope, receive, send)
  File "/Library/Frameworks/Python.framework/Versions/3.11/lib/python3.11/site-packages/starlette/middleware/cors.py", line 77, in __call__
    await self.app(scope, receive, send)
  File "/Library/Frameworks/Python.framework/Versions/3.11/lib/python3.11/site-packages/starlette/middleware/exceptions.py", line 62, in __call__
    await wrap_app_handling_exceptions(self.app, conn)(scope, receive, send)
  File "/Library/Frameworks/Python.framework/Versions/3.11/lib/python3.11/site-packages/starlette/_exception_handler.py", line 53, in wrapped_app
    raise exc
  File "/Library/Frameworks/Python.framework/Versions/3.11/lib/python3.11/site-packages/starlette/_exception_handler.py", line 42, in wrapped_app
    await app(scope, receive, sender)
  File "/Library/Frameworks/Python.framework/Versions/3.11/lib/python3.11/site-packages/starlette/routing.py", line 714, in __call__
    await self.middleware_stack(scope, receive, send)
  File "/Library/Frameworks/Python.framework/Versions/3.11/lib/python3.11/site-packages/starlette/routing.py", line 734, in app
    await route.handle(scope, receive, send)
  File "/Library/Frameworks/Python.framework/Versions/3.11/lib/python3.11/site-packages/starlette/routing.py", line 362, in handle
    await self.app(scope, receive, send)
  File "/Library/Frameworks/Python.framework/Versions/3.11/lib/python3.11/site-packages/starlette/routing.py", line 95, in app
    await wrap_app_handling_exceptions(app, session)(scope, receive, send)
  File "/Library/Frameworks/Python.framework/Versions/3.11/lib/python3.11/site-packages/starlette/_exception_handler.py", line 53, in wrapped_app
    raise exc
  File "/Library/Frameworks/Python.framework/Versions/3.11/lib/python3.11/site-packages/starlette/_exception_handler.py", line 42, in wrapped_app
    await app(scope, receive, sender)
  File "/Library/Frameworks/Python.framework/Versions/3.11/lib/python3.11/site-packages/starlette/routing.py", line 93, in app
    await func(session)
  File "/Library/Frameworks/Python.framework/Versions/3.11/lib/python3.11/site-packages/fastapi/routing.py", line 383, in app
    await dependant.call(**solved_result.values)
  File "/Users/will/Cursor Project/TradingView/OKX DASHBOARD/backend/main.py", line 165, in websocket_endpoint
    await websocket.send_json({"account": idx, "data": data})
  File "/Library/Frameworks/Python.framework/Versions/3.11/lib/python3.11/site-packages/starlette/websockets.py", line 175, in send_json
    await self.send({"type": "websocket.send", "text": text})
  File "/Library/Frameworks/Python.framework/Versions/3.11/lib/python3.11/site-packages/starlette/websockets.py", line 88, in send
    raise WebSocketDisconnect(code=1006)
starlette.websockets.WebSocketDisconnect
INFO:     connection closed
INFO:     127.0.0.1:53995 - "WebSocket /ws" [accepted]
INFO:     connection open
INFO:     connection closed
INFO:     127.0.0.1:54003 - "WebSocket /ws" [accepted]
INFO:     connection open
ERROR:    Exception in ASGI application
Traceback (most recent call last):
  File "/Library/Frameworks/Python.framework/Versions/3.11/lib/python3.11/site-packages/uvicorn/protocols/websockets/websockets_impl.py", line 332, in asgi_send
    await self.send(data)  # type: ignore[arg-type]
    ^^^^^^^^^^^^^^^^^^^^^
  File "/Library/Frameworks/Python.framework/Versions/3.11/lib/python3.11/site-packages/websockets/legacy/protocol.py", line 632, in send
    await self.write_frame(True, opcode, data)
  File "/Library/Frameworks/Python.framework/Versions/3.11/lib/python3.11/site-packages/websockets/legacy/protocol.py", line 1191, in write_frame
    await self.drain()
  File "/Library/Frameworks/Python.framework/Versions/3.11/lib/python3.11/site-packages/websockets/legacy/protocol.py", line 1180, in drain
    await self.ensure_open()
  File "/Library/Frameworks/Python.framework/Versions/3.11/lib/python3.11/site-packages/websockets/legacy/protocol.py", line 921, in ensure_open
    raise self.connection_closed_exc()
websockets.exceptions.ConnectionClosedError: no close frame received or sent

The above exception was the direct cause of the following exception:

Traceback (most recent call last):
  File "/Library/Frameworks/Python.framework/Versions/3.11/lib/python3.11/site-packages/starlette/websockets.py", line 85, in send
    await self._send(message)
  File "/Library/Frameworks/Python.framework/Versions/3.11/lib/python3.11/site-packages/starlette/_exception_handler.py", line 39, in sender
    await send(message)
  File "/Library/Frameworks/Python.framework/Versions/3.11/lib/python3.11/site-packages/uvicorn/protocols/websockets/websockets_impl.py", line 345, in asgi_send
    raise ClientDisconnected from exc
uvicorn.protocols.utils.ClientDisconnected

During handling of the above exception, another exception occurred:

Traceback (most recent call last):
  File "/Library/Frameworks/Python.framework/Versions/3.11/lib/python3.11/site-packages/uvicorn/protocols/websockets/websockets_impl.py", line 244, in run_asgi
    result = await self.app(self.scope, self.asgi_receive, self.asgi_send)  # type: ignore[func-returns-value]
             ^^^^^^^^^^^^^^^^^^^^^^^^^^^^^^^^^^^^^^^^^^^^^^^^^^^^^^^^^^^^^
  File "/Library/Frameworks/Python.framework/Versions/3.11/lib/python3.11/site-packages/uvicorn/middleware/proxy_headers.py", line 60, in __call__
    return await self.app(scope, receive, send)
           ^^^^^^^^^^^^^^^^^^^^^^^^^^^^^^^^^^^^
  File "/Library/Frameworks/Python.framework/Versions/3.11/lib/python3.11/site-packages/fastapi/applications.py", line 1054, in __call__
    await super().__call__(scope, receive, send)
  File "/Library/Frameworks/Python.framework/Versions/3.11/lib/python3.11/site-packages/starlette/applications.py", line 112, in __call__
    await self.middleware_stack(scope, receive, send)
  File "/Library/Frameworks/Python.framework/Versions/3.11/lib/python3.11/site-packages/starlette/middleware/errors.py", line 152, in __call__
    await self.app(scope, receive, send)
  File "/Library/Frameworks/Python.framework/Versions/3.11/lib/python3.11/site-packages/starlette/middleware/cors.py", line 77, in __call__
    await self.app(scope, receive, send)
  File "/Library/Frameworks/Python.framework/Versions/3.11/lib/python3.11/site-packages/starlette/middleware/exceptions.py", line 62, in __call__
    await wrap_app_handling_exceptions(self.app, conn)(scope, receive, send)
  File "/Library/Frameworks/Python.framework/Versions/3.11/lib/python3.11/site-packages/starlette/_exception_handler.py", line 53, in wrapped_app
    raise exc
  File "/Library/Frameworks/Python.framework/Versions/3.11/lib/python3.11/site-packages/starlette/_exception_handler.py", line 42, in wrapped_app
    await app(scope, receive, sender)
  File "/Library/Frameworks/Python.framework/Versions/3.11/lib/python3.11/site-packages/starlette/routing.py", line 714, in __call__
    await self.middleware_stack(scope, receive, send)
  File "/Library/Frameworks/Python.framework/Versions/3.11/lib/python3.11/site-packages/starlette/routing.py", line 734, in app
    await route.handle(scope, receive, send)
  File "/Library/Frameworks/Python.framework/Versions/3.11/lib/python3.11/site-packages/starlette/routing.py", line 362, in handle
    await self.app(scope, receive, send)
  File "/Library/Frameworks/Python.framework/Versions/3.11/lib/python3.11/site-packages/starlette/routing.py", line 95, in app
    await wrap_app_handling_exceptions(app, session)(scope, receive, send)
  File "/Library/Frameworks/Python.framework/Versions/3.11/lib/python3.11/site-packages/starlette/_exception_handler.py", line 53, in wrapped_app
    raise exc
  File "/Library/Frameworks/Python.framework/Versions/3.11/lib/python3.11/site-packages/starlette/_exception_handler.py", line 42, in wrapped_app
    await app(scope, receive, sender)
  File "/Library/Frameworks/Python.framework/Versions/3.11/lib/python3.11/site-packages/starlette/routing.py", line 93, in app
    await func(session)
  File "/Library/Frameworks/Python.framework/Versions/3.11/lib/python3.11/site-packages/fastapi/routing.py", line 383, in app
    await dependant.call(**solved_result.values)
  File "/Users/will/Cursor Project/TradingView/OKX DASHBOARD/backend/main.py", line 165, in websocket_endpoint
    await websocket.send_json({"account": idx, "data": data})
  File "/Library/Frameworks/Python.framework/Versions/3.11/lib/python3.11/site-packages/starlette/websockets.py", line 175, in send_json
    await self.send({"type": "websocket.send", "text": text})
  File "/Library/Frameworks/Python.framework/Versions/3.11/lib/python3.11/site-packages/starlette/websockets.py", line 88, in send
    raise WebSocketDisconnect(code=1006)
starlette.websockets.WebSocketDisconnect
INFO:     connection closed
INFO:     127.0.0.1:54007 - "WebSocket /ws" [accepted]
INFO:     connection open
INFO:     connection closed
INFO:     127.0.0.1:54011 - "WebSocket /ws" [accepted]
INFO:     connection open
ERROR:    Exception in ASGI application
Traceback (most recent call last):
  File "/Library/Frameworks/Python.framework/Versions/3.11/lib/python3.11/site-packages/uvicorn/protocols/websockets/websockets_impl.py", line 332, in asgi_send
    await self.send(data)  # type: ignore[arg-type]
    ^^^^^^^^^^^^^^^^^^^^^
  File "/Library/Frameworks/Python.framework/Versions/3.11/lib/python3.11/site-packages/websockets/legacy/protocol.py", line 632, in send
    await self.write_frame(True, opcode, data)
  File "/Library/Frameworks/Python.framework/Versions/3.11/lib/python3.11/site-packages/websockets/legacy/protocol.py", line 1191, in write_frame
    await self.drain()
  File "/Library/Frameworks/Python.framework/Versions/3.11/lib/python3.11/site-packages/websockets/legacy/protocol.py", line 1180, in drain
    await self.ensure_open()
  File "/Library/Frameworks/Python.framework/Versions/3.11/lib/python3.11/site-packages/websockets/legacy/protocol.py", line 921, in ensure_open
    raise self.connection_closed_exc()
websockets.exceptions.ConnectionClosedError: no close frame received or sent

The above exception was the direct cause of the following exception:

Traceback (most recent call last):
  File "/Library/Frameworks/Python.framework/Versions/3.11/lib/python3.11/site-packages/starlette/websockets.py", line 85, in send
    await self._send(message)
  File "/Library/Frameworks/Python.framework/Versions/3.11/lib/python3.11/site-packages/starlette/_exception_handler.py", line 39, in sender
    await send(message)
  File "/Library/Frameworks/Python.framework/Versions/3.11/lib/python3.11/site-packages/uvicorn/protocols/websockets/websockets_impl.py", line 345, in asgi_send
    raise ClientDisconnected from exc
uvicorn.protocols.utils.ClientDisconnected

During handling of the above exception, another exception occurred:

Traceback (most recent call last):
  File "/Library/Frameworks/Python.framework/Versions/3.11/lib/python3.11/site-packages/uvicorn/protocols/websockets/websockets_impl.py", line 244, in run_asgi
    result = await self.app(self.scope, self.asgi_receive, self.asgi_send)  # type: ignore[func-returns-value]
             ^^^^^^^^^^^^^^^^^^^^^^^^^^^^^^^^^^^^^^^^^^^^^^^^^^^^^^^^^^^^^
  File "/Library/Frameworks/Python.framework/Versions/3.11/lib/python3.11/site-packages/uvicorn/middleware/proxy_headers.py", line 60, in __call__
    return await self.app(scope, receive, send)
           ^^^^^^^^^^^^^^^^^^^^^^^^^^^^^^^^^^^^
  File "/Library/Frameworks/Python.framework/Versions/3.11/lib/python3.11/site-packages/fastapi/applications.py", line 1054, in __call__
    await super().__call__(scope, receive, send)
  File "/Library/Frameworks/Python.framework/Versions/3.11/lib/python3.11/site-packages/starlette/applications.py", line 112, in __call__
    await self.middleware_stack(scope, receive, send)
  File "/Library/Frameworks/Python.framework/Versions/3.11/lib/python3.11/site-packages/starlette/middleware/errors.py", line 152, in __call__
    await self.app(scope, receive, send)
  File "/Library/Frameworks/Python.framework/Versions/3.11/lib/python3.11/site-packages/starlette/middleware/cors.py", line 77, in __call__
    await self.app(scope, receive, send)
  File "/Library/Frameworks/Python.framework/Versions/3.11/lib/python3.11/site-packages/starlette/middleware/exceptions.py", line 62, in __call__
    await wrap_app_handling_exceptions(self.app, conn)(scope, receive, send)
  File "/Library/Frameworks/Python.framework/Versions/3.11/lib/python3.11/site-packages/starlette/_exception_handler.py", line 53, in wrapped_app
    raise exc
  File "/Library/Frameworks/Python.framework/Versions/3.11/lib/python3.11/site-packages/starlette/_exception_handler.py", line 42, in wrapped_app
    await app(scope, receive, sender)
  File "/Library/Frameworks/Python.framework/Versions/3.11/lib/python3.11/site-packages/starlette/routing.py", line 714, in __call__
    await self.middleware_stack(scope, receive, send)
  File "/Library/Frameworks/Python.framework/Versions/3.11/lib/python3.11/site-packages/starlette/routing.py", line 734, in app
    await route.handle(scope, receive, send)
  File "/Library/Frameworks/Python.framework/Versions/3.11/lib/python3.11/site-packages/starlette/routing.py", line 362, in handle
    await self.app(scope, receive, send)
  File "/Library/Frameworks/Python.framework/Versions/3.11/lib/python3.11/site-packages/starlette/routing.py", line 95, in app
    await wrap_app_handling_exceptions(app, session)(scope, receive, send)
  File "/Library/Frameworks/Python.framework/Versions/3.11/lib/python3.11/site-packages/starlette/_exception_handler.py", line 53, in wrapped_app
    raise exc
  File "/Library/Frameworks/Python.framework/Versions/3.11/lib/python3.11/site-packages/starlette/_exception_handler.py", line 42, in wrapped_app
    await app(scope, receive, sender)
  File "/Library/Frameworks/Python.framework/Versions/3.11/lib/python3.11/site-packages/starlette/routing.py", line 93, in app
    await func(session)
  File "/Library/Frameworks/Python.framework/Versions/3.11/lib/python3.11/site-packages/fastapi/routing.py", line 383, in app
    await dependant.call(**solved_result.values)
  File "/Users/will/Cursor Project/TradingView/OKX DASHBOARD/backend/main.py", line 165, in websocket_endpoint
    await websocket.send_json({"account": idx, "data": data})
  File "/Library/Frameworks/Python.framework/Versions/3.11/lib/python3.11/site-packages/starlette/websockets.py", line 175, in send_json
    await self.send({"type": "websocket.send", "text": text})
  File "/Library/Frameworks/Python.framework/Versions/3.11/lib/python3.11/site-packages/starlette/websockets.py", line 88, in send
    raise WebSocketDisconnect(code=1006)
starlette.websockets.WebSocketDisconnect
INFO:     connection closed
INFO:     127.0.0.1:54013 - "WebSocket /ws" [accepted]
INFO:     connection open
INFO:     Shutting down
INFO:     connection closed
INFO:     Waiting for application shutdown.
INFO:     Application shutdown complete.
INFO:     Finished server process [47079]
INFO:     Stopping reloader process [47012]
